2025-01-24 17:02:25,545 This is info
2025-01-24 17:02:25,546 debugger
2025-01-24 17:02:25,546 warning
2025-01-29 11:29:21,989 This is info
2025-01-29 11:29:21,989 debugger
2025-01-29 11:29:21,989 warning
2025-01-29 11:29:24,166 this is the start and am entering 4 and 5
2025-01-29 11:29:24,167 Executed successfully
2025-01-29 11:36:33,347 This is info
2025-01-29 11:36:33,347 debugger
2025-01-29 11:36:33,347 warncovming
2025-01-29 11:37:22,749 this is the start and am entering 4 and 5
2025-01-29 11:37:22,749 Executed successfully
2025-01-29 11:37:49,587 this is the start and am entering 3 and 0
2025-01-29 11:37:49,587 Error has happened
2025-01-29 11:37:49,587 Exception has occureddivision by zero
Traceback (most recent call last):
  File "/tmp/ipykernel_381190/958697927.py", line 4, in divbyzero
    div = a/b
          ~^~
ZeroDivisionError: division by zero
2025-01-29 11:38:05,739 this is the start and am entering 3 and 0
2025-01-29 11:38:05,739 Error has happened
2025-01-29 11:38:05,739 Exception has occureddivision by zero
Traceback (most recent call last):
  File "/tmp/ipykernel_381190/958697927.py", line 4, in divbyzero
    div = a/b
          ~^~
ZeroDivisionError: division by zero
2025-01-29 11:40:21,065 this is the start and am entering 4 and 5
2025-01-29 11:40:21,065 Executed successfully
2025-01-29 11:40:22,407 this is the start and am entering 3 and 0
2025-01-29 11:40:22,407 Error has happened
2025-01-29 11:40:22,407 Exception has occureddivision by zero
Traceback (most recent call last):
  File "/tmp/ipykernel_393511/958697927.py", line 4, in divbyzero
    div = a/b
          ~^~
ZeroDivisionError: division by zero
